[2025-07-23T15:05:38.938+0000] {scheduler_job_runner.py:1562} WARNING - Marking task instance <TaskInstance: 1_python_etl_and_star_schema.clean_raw_data manual__2025-07-23T14:54:29.695716+00:00 [queued]> stuck in queued as failed. If the task instance has available retries, it will be retried.
[2025-07-23T15:05:40.048+0000] {scheduler_job_runner.py:769} ERROR - Executor reports task instance <TaskInstance: 1_python_etl_and_star_schema.clean_raw_data manual__2025-07-23T14:54:29.695716+00:00 [queued]> finished (failed) although the task says it's queued. (Info: None) Was the task killed externally?
